Workbook

Sheet 2026年费控系统预算数据收集表
A1: 公司代码 | B1: 公司名称 | C1: 预算科目名称 | D1: 事业部编码 | E1: 事业部名称 | F1: 生产单元编码 | G1: 生产单元名称 | H1: 一级部门编码 | I1: 一级部门名称 | J1: 2026年预算金额（单位：元） | K1: 1月 | L1: 2月 | M1: 3月 | N1: 4月 | O1: 5月 | P1: 6月 | Q1: 7月 | R1: 8月 | S1: 9月 | T1: 10月 | U1: 11月 | V1: 12月
A2: 1000 | B2: =VLOOKUP(A2,公司代码公司名称对照表!A:B,2,0) -> 三安光电股份有限公司 | C2: IT办公费 | D2: 01 | E2: =VLOOKUP(D2,事业部生产单元对照表!A:B,2,0) -> 氮化镓 | F2: 02 | G2: =VLOOKUP(F2,事业部生产单元对照表!E:F,2,0) -> 南安生产单元(GaN) | H2: 01 | I2: =VLOOKUP(H2,一级部门对照表!B:C,2,0) -> 研发\技术 | J2: =SUM(K2:V2) -> 0
C3: IT订阅费 | J3: =SUM(K3:V3) -> 0
C4: IT人力委外 | J4: =SUM(K4:V4) -> 0
C5: IT软件维护 | J5: =SUM(K5:V5) -> 0
C6: IT维修费 | J6: =SUM(K6:V6) -> 0
C7: IT硬件维护 | J7: =SUM(K7:V7) -> 0
C8: IT租赁费 | J8: =SUM(K8:V8) -> 0
C9: 安全生产费 | J9: =SUM(K9:V9) -> 0
C10: 部门活动经费 | J10: =SUM(K10:V10) -> 0
C11: 财务费用 | J11: =SUM(K11:V11) -> 0
C12: 财务咨询审计费 | J12: =SUM(K12:V12) -> 0
C13: 残保金 | J13: =SUM(K13:V13) -> 0
C14: 仓储费 | J14: =SUM(K14:V14) -> 0
... C31: 捐赠支出 | J31: =SUM(K31:V31) -> 0
C32: 劳务费
C33: 零星工程
C34: 履约保证金
C35: 履约成本运输费
C36: 绿化费
C37: 内部加工费
C38: 品管测试检验费
C39: 品管产品认证费
C40: 品管其他福利费
C41: 品管体系认证费
C42: 其他诉讼费
C43: 汽车费用
... C81: 租赁费

Sheet Sheet4
A1: 预算科目名称（必填） | B1: 允许占用此科目的费用类型（选填）
A2: IT办公费 | B2: ZY55
A3: IT订阅费 | B3: ZY72
A4: IT人力委外 | B4: ZY64
A5: IT软件维护 | B5: ZY62
A6: IT维修费 | B6: ZY167 | C6: SA127 | D6: SA128
A7: IT硬件维护 | B7: ZY63
A8: IT租赁费 | B8: SA56
A9: 安全生产费 | B9: SA148 | C9: ZY113 | D9: SA151 | E9: ZY94 | F9: ZY101 | G9: SA152 | H9: ZY97 | I9: ZY91 | J9: ZY92 | K9: ZY89 | L9: ZY99 | M9: SA149 | N9: ZY102 | O9: ZY96 | P9: ZY93 | Q9: ZY98 | R9: ZY100 | S9: ZY90 | T9: ZY95 | U9: SA150 | V9: ZY60
A10: 部门活动经费 | B10: SA36
A11: 财务费用 | B11: SA169 | C11: SA171 | D11: SA168 | E11: SA170
A12: 财务咨询审计费 | B12: SA110
A13: 残保金 | B13: SA55
A14: 仓储费 | B14: ZY131
A15: 差旅费 | B15: SA76 | C15: SA75 | D15: SA65 | E15: SA74 | F15: SA64 | G15: SA66 | H15: SA68 | I15: SA67
A16: 产品质量保证 | B16: SA154
A17: 出口费用 | B17: SA125
A18: 代理服务 | B18: SA134
A19: 董事会会费 | B19: SA166
A20: 风控咨询审计费 | B20: SA116 | C20: SA113
A21: 工会经费 | B21: SA53
A22: 工装治具维护修理 | B22: ZY114
A23: 固定电话费 | B23: SA86
A24: 环保费 | B24: ZY73 | C24: ZY75 | D24: ZY74 | E24: ZY82 | F24: ZY76 | G24: ZY81 | H24: ZY77 | I24: ZY80 | J24: ZY78 | K24: ZY79
A25: 基建维修费 | B25: SA132 | C25: ZY168
A26: 技术服务费 | B26: SA122
A27: 技术开发费 | B27: ZY132
A28: 技术中心会务宣传费 | B28: ZY128
A29: 技术中心专项审计费 | B29: SA114
A30: 进口费用 | B30: SA124
A31: 捐赠支出 | B31: SA179
A32: 劳务费 | B32: SA54
A33: 零星工程 | B33: ZY166
A34: 履约保证金 | B34: SA174
A35: 履约成本运输费 | B35: SA172 | C35: SA173
A36: 绿化费 | B36: ZY57 | C36: ZY83
A37: 内部加工费 | B37: ZY115
A38: 品管测试检验费 | B38: ZY110 | C38: ZY06 | D38: ZY07 | E38: ZY108
A39: 品管产品认证费 | B39: SA155
A40: 品管其他福利费 | B40: ZY61
...

Sheet Sheet3
A1: 费用类型名称（必填） | B1: 编码前缀（选填） | C1: 编码（选填） | F1: 费用类型名称（必填）
A2: 差旅费-商旅机票费 | C2: SA69 | D2: =VLOOKUP(C2,费控系统预算科目明细表!G:G,1,0) -> SA69 | F2: 差旅费-商旅机票费
A3: 差旅费-商旅长途汽车费用 | C3: SA72 | D3: =VLOOKUP(C3,费控系统预算科目明细表!G:G,1,0) -> SA72 | F3: 差旅费-商旅长途汽车费用
A4: 差旅费-商旅火车费用 | C4: SA71 | D4: =VLOOKUP(C4,费控系统预算科目明细表!G:G,1,0) -> SA71 | F4: 差旅费-商旅火车费用
A5: 差旅费-商旅住宿费 | C5: SA70 | D5: =VLOOKUP(C5,费控系统预算科目明细表!G:G,1,0) -> SA70 | F5: 差旅费-商旅住宿费
A6: 差旅费-商旅市内交通费 | C6: SA73 | D6: =VLOOKUP(C6,费控系统预算科目明细表!G:G,1,0) -> SA73 | F6: 差旅费-商旅市内交通费
A7: 差旅费-商旅其他费用（含退改签） | D7: =VLOOKUP(C7,费控系统预算科目明细表!G:G,1,0) -> #N/A | F7: 差旅费-商旅其他费用（含退改签）
A8: 差旅费-机票费 | C8: SA64 | D8: =VLOOKUP(C8,费控系统预算科目明细表!G:G,1,0) -> SA64 | F8: 差旅费-机票费
A9: 住宿 | C9: 01.002 | D9: =VLOOKUP(C9,费控系统预算科目明细表!G:G,1,0) -> #N/A | F9: 住宿
A10: 飞机 | C10: 01.003 | D10: =VLOOKUP(C10,费控系统预算科目明细表!G:G,1,0) -> #N/A | F10: 飞机
A11: 火车 | C11: 01.005 | D11: =VLOOKUP(C11,费控系统预算科目明细表!G:G,1,0) -> #N/A | F11: 火车
A12: 长途汽车 | C12: 01.006 | D12: =VLOOKUP(C12,费控系统预算科目明细表!G:G,1,0) -> #N/A | F12: 长途汽车
A13: 里程补贴 | D13: =VLOOKUP(C13,费控系统预算科目明细表!G:G,1,0) -> #N/A | F13: 里程补贴
A14: 员工轮船 | D14: =VLOOKUP(C14,费控系统预算科目明细表!G:G,1,0) -> #N/A | F14: 员工轮船
A15: 差旅费-住宿费 | C15: SA65 | D15: =VLOOKUP(C15,费控系统预算科目明细表!G:G,1,0) -> SA65 | F15: 差旅费-住宿费
A16: 差旅费-长途汽车费用 | C16: SA67 | D16: =VLOOKUP(C16,费控系统预算科目明细表!G:G,1,0) -> SA67 | F16: 差旅费-长途汽车费用
A17: 差旅费-火车费用 | C17: SA66 | D17: =VLOOKUP(C17,费控系统预算科目明细表!G:G,1,0) -> SA66 | F17: 差旅费-火车费用
A18: 差旅费-市内交通费 | C18: SA68 | D18: =VLOOKUP(C18,费控系统预算科目明细表!G:G,1,0) -> SA68 | F18: 差旅费-市内交通费
A19: 差旅费-差旅补贴 | C19: SA74 | D19: =VLOOKUP(C19,费控系统预算科目明细表!G:G,1,0) -> SA74 | F19: 差旅费-差旅补贴
A20: 差旅费-误餐补贴 | C20: SA75 | D20: =VLOOKUP(C20,费控系统预算科目明细表!G:G,1,0) -> SA75 | F20: 差旅费-误餐补贴
A21: 差旅费-其他差旅费（含退改签） | C21: SA76 | D21: =VLOOKUP(C21,费控系统预算科目明细表!G:G,1,0) -> SA76 | F21: 差旅费-其他差旅费（含退改签）
A22: 出差差旅费用 | D22: =VLOOKUP(C22,费控系统预算科目明细表!G:G,1,0) -> #N/A | F22: 出差差旅费用
A23: 离职经济补偿金 | C23: SA01 | D23: =VLOOKUP(C23,费控系统预算科目明细表!G:G,1,0) -> SA01 | F23: 离职经济补偿金
A24: 竞业限制补偿金 | C24: SA02 | D24: =VLOOKUP(C24,费控系统预算科目明细表!G:G,1,0) -> SA02 | F24: 竞业限制补偿金
A25: 宿舍福利-卫星电视费 | C25: SA06 | D25: =VLOOKUP(C25,费控系统预算科目明细表!G:G,1,0) -> SA06 | F25: 宿舍福利-卫星电视费
A26: 宿舍福利-其他费用 | C26: SA12 | D26: =VLOOKUP(C26,费控系统预算科目明细表!G:G,1,0) -> SA12 | F26: 宿舍福利-其他费用
A27: 其他福利-节日福利 | C27: SA24 | D27: =VLOOKUP(C27,费控系统预算科目明细表!G:G,1,0) -> SA24 | F27: 其他福利-节日福利
A28: 其他福利-职工医疗互助费用 | C28: SA22 | D28: =VLOOKUP(C28,费控系统预算科目明细表!G:G,1,0) -> SA22 | F28: 其他福利-职工医疗互助费用
A29: 其他福利-外租档口结算 | C29: SA18 | D29: =VLOOKUP(C29,费控系统预算科目明细表!G:G,1,0) -> SA18 | F29: 其他福利-外租档口结算
A30: 其他福利-员工体检费 | C30: SA21 | D30: =VLOOKUP(C30,费控系统预算科目明细表!G:G,1,0) -> SA21 | F30: 其他福利-员工体检费
A31: 食堂福利-其他费用 | C31: SA20 | D31: =VLOOKUP(C31,费控系统预算科目明细表!G:G,1,0) -> SA20 | F31: 食堂福利-其他费用
A32: 其他福利-司机误餐费用(非出差） | C32: SA26 | D32: =VLOOKUP(C32,费控系统预算科目明细表!G:G,1,0) -> SA26 | F32: 其他福利-司机误餐费用(非出差）
A33: 食堂福利-食堂物资费用 | C33: SA15 | D33: =VLOOKUP(C33,费控系统预算科目明细表!G:G,1,0) -> SA15 | F33: 食堂福利-食堂物资费用
A34: 宿舍福利-家具家电 | C34: ZY106 | D34: =VLOOKUP(C34,费控系统预算科目明细表!G:G,1,0) -> ZY106 | F34: 宿舍福利-家具家电
... A156: 环保费-环保应急物资 | C156: ZY78 | D156: =VLOOKUP(C156,费控系统预算科目明细表!G:G,1,0) -> ZY78 | F156: 环保费-环保应急物资
A157: 公司派车 | D157: =VLOOKUP(C157,费控系统预算科目明细表!G:G,1,0) -> #N/A | F157: 公司派车
A158: 公司派车失败 | D158: =VLOOKUP(C158,费控系统预算科目明细表!G:G,1,0) -> #N/A | F158: 公司派车失败
A159: 租赁费-机器租赁费 | C159: ZY122 | D159: =VLOOKUP(C159,费控系统预算科目明细表!G:G,1,0) -> ZY122 | F159: 租赁费-机器租赁费
A160: 咨询审计费-尽调费用 | C160: SA111 | D160: =VLOOKUP(C160,费控系统预算科目明细表!G:G,1,0) -> SA111 | F160: 咨询审计费-尽调费用
A161: 咨询审计费-法律顾问费用 | C161: SA113 | D161: =VLOOKUP(C161,费控系统预算科目明细表!G:G,1,0) -> SA113 | F161: 咨询审计费-法律顾问费用
...

Sheet 事业部生产单元对照表
A1: 事业部组织编码 | B1: 简称 | E1: 生产单元组织编码 | F1: 生产单元
A2: 00 | B2: 股份 | E2: 00 | F2: 本部职能
A3: 01 | B3: 氮化镓 | E3: 01 | F3: 厦门生产单元
A4: 02 | B4: 砷化镓 | E4: 02 | F4: 南安生产单元(GaN)
A5: 03 | B5: 特种应用 | E5: 03 | F5: 南安生产单元(衬底)
A6: 05 | B6: 射频 | E6: 05 | F6: 安溪生产单元
A7: 06 | B7: 电力电子 | E7: 06 | F7: 芜湖生产单元
A8: 08 | B8: 安瑞 | E8: 07 | F8: 鄂州生产单元
A9: 09 | B9: 光通讯 | E9: 08 | F9: 南安生产单元(GaAs)
A10: 10 | B10: LDI | E10: 09 | F10: 天津生产单元
A11: 11 | B11: 北京三安 | E11: 10 | F11: 新材料生产单元
A12: 12 | B12: 安徽科技 | E12: 11 | F12: RGB生产单元
... A17: 97 | B17: 香港灯条 | E17: 17 | F17: 湖南三安生产单元
E18: 18 | F18: 重庆三安生产单元
E19: 20 | F19: 欧洲分公司
E20: 21 | F20: APC
E21: 22 | F21: 安瑞芜湖生产单元
E22: 23 | F22: 台州分公司
E23: 25 | F23: 重庆分公司
E24: 26 | F24: 南京分公司
E25: 27 | F25: WIPAC
E26: 28 | F26: 泉州光通讯生产单元
E27: 29 | F27: 国际代工生产单元
E28: 30 | F28: LED销售部
E29: 35 | F29: 厦门科技生产单元
... E39: 98 | F39: 南安生产单元(GaAs)-公共

Sheet 公司代码公司名称对照表
A1: 公司代码 | B1: 公司名称
A2: 1000 | B2: 三安光电股份有限公司
A3: 2010 | B3: 厦门市三安光电科技有限公司
A4: 2020 | B4: 天津三安光电有限公司
A5: 2030 | B5: 安徽三安光电有限公司
A6: 2040 | B6: 安徽三安气体有限公司
A7: 2050 | B7: 福建晶安光电有限公司
A8: 2060 | B8: Luminus Inc.
A9: 2070 | B9: Luminus Devices Inc.
A10: 2080 | B10: 朗明纳斯（香港）有限公司
A11: 2090 | B11: 朗明纳斯光电（厦门）有限公司
A12: 2100 | B12: 厦门三安光电有限公司
... A43: 9010 | B43: 安徽三首光电有限公司

Sheet 2026年费控系统预算数据收集表 (2)
A1: 公司代码 | B1: 预算科目名称 | C1: 预算归口部门 | D1: 2026年预算金额 | E1: 1月 | F1: 2月 | G1: 3月 | H1: 4月 | I1: 5月 | J1: 6月 | K1: 7月 | L1: 8月 | M1: 9月 | N1: 10月 | O1: 11月 | P1: 12月
B2: IT办公费 | C2: IT
C3: 00 | D3: 总经理室
C4: 01 | D4: 研发部
C5: 02 | D5: 运营
C6: 03 | D6: 采购
C7: 05 | D7: 品管
C8: 06 | D8: 总经办
C9: 07 | D9: 人资
C10: 08 | D10: 财务
C11: 09 | D11: 信息化
C12: 10 | D12: 证券
C13: 11 | D13: 基建
C14: 12 | D14: 风控
... C43: 42 | D43: 技术委员会
B44: IT订阅费 | C44: IT
C45: 00 | D45: 总经理室
C46: 01 | D46: 研发部
C47: 02 | D47: 运营
C48: 03 | D48: 采购
C49: 05 | D49: 品管
C50: 06 | D50: 总经办
C51: 07 | D51: 人资
C52: 08 | D52: 财务
C53: 09 | D53: 信息化
C54: 10 | D54: 证券
C55: 11 | D55: 基建
C56: 12 | D56: 风控
... C85: 42 | D85: 技术委员会
B86: IT人力委外 | C86: IT
C87: 00 | D87: 总经理室
C88: 01 | D88: 研发部
C89: 02 | D89: 运营
C90: 03 | D90: 采购
C91: 05 | D91: 品管
C92: 06 | D92: 总经办
C93: 07 | D93: 人资
C94: 08 | D94: 财务
C95: 09 | D95: 信息化
C96: 10 | D96: 证券
...

Sheet 一级部门对照表
B1: 一级部门编码 | C1: 部门名称
B2: 00 | C2: 总经理室
B3: 01 | C3: 研发\技术
B4: 02 | C4: 运营
B5: 03 | C5: 采购
B6: 05 | C6: 品管
B7: 06 | C7: 总经办
B8: 07 | C8: 人资
B9: 08 | C9: 财务
B10: 09 | C10: 信息化
B11: 10 | C11: 证券
B12: 11 | C12: 基建
... B42: 42 | C42: 技术委员会

Sheet Sheet5
A1: 预算科目名称 | B1: 编码
A2: IT办公费 | B2: ZY55 | D2: ZY55 | E2: =D2=B2 -> TRUE
A3: IT订阅费 | B3: ZY72 | D3: ZY72 | E3: =D3=B3 -> TRUE
A4: IT人力委外 | B4: ZY64 | D4: ZY64 | E4: =D4=B4 -> TRUE
A5: IT软件维护 | B5: ZY62 | D5: ZY62 | E5: =D5=B5 -> TRUE
A6: IT维修费 | B6: SA127 | D6: SA127 | E6: =D6=B6 -> TRUE
B7: SA128 | D7: SA128 | E7: =D7=B7 -> TRUE
B8: ZY167 | D8: ZY167 | E8: =D8=B8 -> TRUE
A9: IT硬件维护 | B9: ZY63 | D9: ZY63 | E9: =D9=B9 -> TRUE
A10: IT租赁费 | B10: SA56 | D10: SA56 | E10: =D10=B10 -> TRUE
A11: 安全生产费 | B11: SA148 | D11: SA148 | E11: =D11=B11 -> TRUE
B12: SA149 | D12: SA149 | E12: =D12=B12 -> TRUE
B13: SA150 | D13: SA150 | E13: =D13=B13 -> TRUE
B14: SA151 | D14: SA151 | E14: =D14=B14 -> TRUE
B15: SA152 | D15: SA152 | E15: =D15=B15 -> TRUE
B16: ZY100 | D16: ZY100 | E16: =D16=B16 -> TRUE
B17: ZY101 | D17: ZY101 | E17: =D17=B17 -> TRUE
B18: ZY102 | D18: ZY102 | E18: =D18=B18 -> TRUE
B19: ZY113 | D19: ZY113 | E19: =D19=B19 -> TRUE
B20: ZY60 | D20: ZY60 | E20: =D20=B20 -> TRUE
B21: ZY89 | D21: ZY89 | E21: =D21=B21 -> TRUE
B22: ZY90 | D22: ZY90 | E22: =D22=B22 -> TRUE
B23: ZY91 | D23: ZY91 | E23: =D23=B23 -> TRUE
... B31: ZY99 | D31: ZY99 | E31: =D31=B31 -> TRUE
A32: 部门活动经费 | B32: SA36 | D32: SA36 | E32: =D32=B32 -> TRUE
A33: 财务费用 | B33: SA168 | D33: SA168 | E33: =D33=B33 -> TRUE
B34: SA169 | D34: SA169 | E34: =D34=B34 -> TRUE
B35: SA170 | D35: SA170 | E35: =D35=B35 -> TRUE
B36: SA171 | D36: SA171 | E36: =D36=B36 -> TRUE
A37: 财务咨询审计费 | B37: SA110 | D37: SA110 | E37: =D37=B37 -> TRUE
A38: 残保金 | B38: SA55 | D38: SA55 | E38: =D38=B38 -> TRUE
A39: 仓储费 | B39: ZY131 | D39: ZY131 | E39: =D39=B39 -> TRUE
A40: 差旅费 | B40: SA64 | D40: SA64 | E40: =D40=B40 -> TRUE
B41: SA65 | D41: SA65 | E41: =D41=B41 -> TRUE
B42: SA66 | D42: SA66 | E42: =D42=B42 -> TRUE
B43: SA67 | D43: SA67 | E43: =D43=B43 -> TRUE
B44: SA68 | D44: SA68 | E44: =D44=B44 -> TRUE
B45: SA74 | D45: SA74 | E45: =D45=B45 -> TRUE
B46: SA75 | D46: SA75 | E46: =D46=B46 -> TRUE
B47: SA76 | D47: SA76 | E47: =D47=B47 -> TRUE
...

Sheet 费控系统预算科目明细表
A1: 会计科目编码 | B1: 会计科目名称 | C1: 所属分类名称-新分类名称 | D1: 费用类型名称 （必填）-费控系统 | E1: 预算科目名称 | F1: 预算归口部门(按会计科目） | G1: 编码
A2: 6600010124 | B2: 人工-员工辞退福利（裁剪冗员补偿款） | C2: 离职费用 | D2: 离职经济补偿金 | E2: 员工辞退成本 | F2: 人资 | G2: =VLOOKUP(D2,Sheet3!A:C,3,0) -> SA01
A3: 6600010124 | B3: 人工-员工辞退福利（裁剪冗员补偿款） | C3: 离职费用 | D3: 竞业限制补偿金 | E3: 员工辞退成本 | F3: 人资 | G3: =VLOOKUP(D3,Sheet3!A:C,3,0) -> SA02
A4: 6600010201 | B4: 人工-福利费用-宿舍费用 | C4: 福利费用 | D4: 宿舍福利-房租 | E4: 宿舍费用 | F4: 总办 | G4: =VLOOKUP(D4,Sheet3!A:C,3,0) -> SA03
A5: 6600010201 | B5: 人工-福利费用-宿舍费用 | C5: 福利费用 | D5: 宿舍福利-能源费用 | E5: 宿舍费用 | F5: 总办 | G5: =VLOOKUP(D5,Sheet3!A:C,3,0) -> SA04
A6: 6600010201 | B6: 人工-福利费用-宿舍费用 | C6: 福利费用 | D6: 宿舍福利-能源费用 | E6: 宿舍费用 | F6: 总办 | G6: =VLOOKUP(D6,Sheet3!A:C,3,0) -> SA04
A7: 6600010201 | B7: 人工-福利费用-宿舍费用 | C7: 福利费用 | D7: 宿舍福利-能源费用 | E7: 宿舍费用 | F7: 总办 | G7: =VLOOKUP(D7,Sheet3!A:C,3,0) -> SA04
A8: 6600010201 | B8: 人工-福利费用-宿舍费用 | C8: 福利费用 | D8: 宿舍福利-物业费 | E8: 宿舍费用 | F8: 总办 | G8: =VLOOKUP(D8,Sheet3!A:C,3,0) -> SA05
A9: 6600010201 | B9: 人工-福利费用-宿舍费用 | C9: 修理费 | D9: 宿舍福利-修理费 | E9: 宿舍费用 | F9: 总办 | G9: =VLOOKUP(D9,Sheet3!A:C,3,0) -> ZY58
A10: 6600010201 | B10: 人工-福利费用-宿舍费用 | C10: 福利费用 | D10: 宿舍福利-卫星电视费 | E10: 宿舍费用 | F10: 总办 | G10: =VLOOKUP(D10,Sheet3!A:C,3,0) -> SA06
A11: 6600010201 | B11: 人工-福利费用-宿舍费用 | C11: 福利费用 | D11: 宿舍福利-宽带网络费用 | E11: 宿舍费用 | F11: 总办 | G11: =VLOOKUP(D11,Sheet3!A:C,3,0) -> SA07
A12: 6600010201 | B12: 人工-福利费用-宿舍费用 | C12: 福利费用 | D12: 宿舍福利-奖励费用 | E12: 宿舍费用 | F12: 总办 | G12: =VLOOKUP(D12,Sheet3!A:C,3,0) -> SA08
A13: 6600010201 | B13: 人工-福利费用-宿舍费用 | C13: 福利费用 | D13: 宿舍福利-家具家电 | E13: 宿舍费用 | F13: 总办 | G13: =VLOOKUP(D13,Sheet3!A:C,3,0) -> ZY106
... A146: 6600020304 | B146: 办公运营费-差旅费-其他差旅费 | C146: 差旅费 | D146: 差旅费-误餐补贴 | E146: 差旅费 | F146: 总办 | G146: =VLOOKUP(D146,Sheet3!A:C,3,0) -> SA75
A147: 6600020304 | B147: 办公运营费-差旅费-其他差旅费 | C147: 差旅费 | D147: 差旅费-其他差旅费 | E147: 差旅费 | F147: 总办 | G147: SA76
A148: 6600020401 | B148: 办公运营费-汽车费用-租车 | C148: 办公运营费 | D148: 汽车费用-租车费 | E148: 汽车费用 | F148: 总办 | G148: =VLOOKUP(D148,Sheet3!A:C,3,0) -> SA77
A149: 6600020402 | B149: 办公运营费-汽车费用-燃料 | C149: 办公运营费 | D149: 汽车费用-燃料费 | E149: 汽车费用 | F149: 总办 | G149: =VLOOKUP(D149,Sheet3!A:C,3,0) -> SA78
A150: 6600020403 | B150: 办公运营费-汽车费用-维保 | C150: 办公运营费 | D150: 汽车费用-维保费 | E150: 汽车费用 | F150: 总办 | G150: =VLOOKUP(D150,Sheet3!A:C,3,0) -> SA79
A151: 6600020404 | B151: 办公运营费-汽车费用-路税&保险 | C151: 办公运营费 | D151: 汽车费用-路税&保险 | E151: 汽车费用 | F151: 总办 | G151: =VLOOKUP(D151,Sheet3!A:C,3,0) -> SA80
A152: 6600020405 | B152: 办公运营费-汽车费用-里程津贴 | C152: 办公运营费 | D152: 汽车费用-里程津贴 | E152: 汽车费用 | F152: 总办 | G152: =VLOOKUP(D152,Sheet3!A:C,3,0) -> SA81
A153: 6600020406 | B153: 办公运营费-汽车费用-过路过桥费 | C153: 办公运营费 | D153: 汽车费用-过路过桥费 | E153: 汽车费用 | F153: 总办 | G153: =VLOOKUP(D153,Sheet3!A:C,3,0) -> SA82
A154: 6600020407 | B154: 办公运营费-汽车费用-停车费 | C154: 办公运营费 | D154: 汽车费用-停车费 | E154: 汽车费用 | F154: 总办 | G154: =VLOOKUP(D154,Sheet3!A:C,3,0) -> SA83
A155: 6600020408 | B155: 办公运营费-汽车费用-年检费 | C155: 办公运营费 | D155: 汽车费用-年检费 | E155: 汽车费用 | F155: 总办 | G155: =VLOOKUP(D155,Sheet3!A:C,3,0) -> SA84
A156: 6600020409 | B156: 办公运营费-汽车费用-其他车辆费 | C156: 办公运营费 | D156: 汽车费用-其他车辆费 | E156: 汽车费用 | F156: 总办 | G156: =VLOOKUP(D156,Sheet3!A:C,3,0) -> SA85
A157: 6600020500 | B157: 办公运营费-固定电话费 | C157: 办公运营费 | D157: 固定电话费 | E157: 固定电话费 | F157: IT | G157: =VLOOKUP(D157,Sheet3!A:C,3,0) -> SA86
A158: 6600020600 | B158: 办公运营费-移动电话费 | C158: 办公运营费 | D158: 移动电话费 | E158: 移动电话费 | F158: 总办 | G158: =VLOOKUP(D158,Sheet3!A:C,3,0) -> SA87
A159: 6600020700 | B159: 办公运营费-业务招待费 | C159: 办公运营费 | D159: 业务招待-茶叶费用 | E159: 业务招待费 | F159: 总办 | G159: =VLOOKUP(D159,Sheet3!A:C,3,0) -> SA88
... A244: 6600031501 | B244: 外部服务-工装治具维护修理 | C244: 外部服务 | D244: 工装治具维护修理 | E244: 工装治具维护修理 | F244: 安瑞 | G244: =VLOOKUP(D244,Sheet3!A:C,3,0) -> ZY114
A245: 6600031600 | B245: 外部服务-加工费 | C245: 外部服务 | D245: 内部加工费（工序委外） | E245: 内部加工费 | G245: =VLOOKUP(D245,Sheet3!A:C,3,0) -> ZY115
A246: 6600031600 | B246: 外部服务-加工费 | C246: 外部服务 | D246: 外部加工费（工序委外） | E246: 外部加工费 | G246: =VLOOKUP(D246,Sheet3!A:C,3,0) -> ZY116
A247: 6600031800 | B247: 外部服务-设计费 | C247: 外部服务 | D247: 设计费 | E247: 设计费 | F247: 技术中心 | G247: =VLOOKUP(D247,Sheet3!A:C,3,0) -> ZY119
A248: 6600032000 | B248: 外部服务-委托外部研究开发费用 | C248: 外部服务 | D248: 委托外部研究开发费用 | E248: 委托外部研究开发费用 | F248: 技术中心 | G248: =VLOOKUP(D248,Sheet3!A:C,3,0) -> SA133
A249: 6600032100 | B249: 外部服务-仓储费 | C249: 外部服务 | D249: 产品仓储费 | E249: 仓储费 | F249: 战略 | G249: =VLOOKUP(D249,Sheet3!A:C,3,0) -> ZY131
A250: 6600033001 | B250: 外部服务-清洁费 | C250: 清洁费 | D250: 清洁费-委外清洁 | E250: 总办其他服务费 | F250: 总办 | G250: =VLOOKUP(D250,Sheet3!A:C,3,0) -> ZY117
A251: 6600034100 | B251: 外部服务-水处理费 | C251: 外部服务 | D251: 厂区水处理费（循环水处理） | E251: 运营委外维修费 | F251: 战略 | G251: =VLOOKUP(D251,Sheet3!A:C,3,0) -> ZY120
A252: 6600035100 | B252: 外部服务-代理服务 | C252: 外部服务 | D252: 代理服务费 | E252: 代理服务 | F252: 风控 | G252: =VLOOKUP(D252,Sheet3!A:C,3,0) -> SA134
A253: 6600036100 | B253: 外部服务-销售佣金 | C253: 外部服务 | D253: 销售佣金 | E253: 销售佣金 | F253: 销售部 | G253: =VLOOKUP(D253,Sheet3!A:C,3,0) -> SA135
A254: 6600040200 | B254: 税费-保险费 | C254: 保险费 | D254: 保险费 | E254: 总办其他服务费 | F254: 总办 | G254: =VLOOKUP(D254,Sheet3!A:C,3,0) -> SA136
A255: 6600040300 | B255: 税费-货运保险费 | C255: 保险费 | D255: 货运保险费 | E255: 运营保险费 | F255: 战略 | G255: =VLOOKUP(D255,Sheet3!A:C,3,0) -> SA137
A256: 6600060100 | B256: 材料消耗-物料消耗 | C256: 物料消耗 | D256: 物料消耗 | E256: 运营物料消耗 | F256: 战略 | G256: =VLOOKUP(D256,Sheet3!A:C,3,0) -> SA138
...

Sheet Sheet6
A1: 会计科目编码 | B1: 会计科目名称 | C1: 所属分类名称-新分类名称 | D1: 费用类型名称 （必填）-费控系统 | E1: 预算科目名称 | F1: 预算归口部门(按会计科目） | G1: 编码
A2: 6600031500 | B2: 外部服务-修理费 | C2: SAP物料组 | D2: 零星工程-气体管道一二次配工程 | E2: 零星工程 | F2: 战略 | G2: ZY157 | H2: 新建费用类型
A3: 6600031500 | B3: 外部服务-修理费 | C3: SAP物料组 | D3: 零星工程-一二次配工程 | E3: 零星工程 | F3: 战略 | G3: ZY158 | H3: 新建费用类型
A4: 6600031500 | B4: 外部服务-修理费 | C4: SAP物料组 | D4: 零星工程-动力工程 | E4: 零星工程 | F4: 战略 | G4: ZY159 | H4: 新建费用类型
A5: 6600031500 | B5: 外部服务-修理费 | C5: SAP物料组 | D5: 零星工程-车间工程 | E5: 零星工程 | F5: 战略 | G5: ZY160 | H5: 新建费用类型
A6: 6600031500 | B6: 外部服务-修理费 | C6: SAP物料组 | D6: 零星工程-生管工程 | E6: 零星工程 | F6: 战略 | G6: ZY161 | H6: 新建费用类型
A7: 6600010201 | B7: 人工-福利费用-宿舍费用 | C7: SAP物料组 | D7: 零星工程-总办宿舍工程 | E7: 零星工程 | F7: 战略 | G7: ZY162 | H7: 新建费用类型
A8: 6600010202 | B8: 人工-福利费用-食堂费用 | C8: SAP物料组 | D8: 零星工程-总办食堂工程 | E8: 零星工程 | F8: 战略 | G8: ZY163 | H8: 新建费用类型
A9: 6600021200 | B9: 办公运营费-环保及绿化费 | C9: SAP物料组 | D9: 零星工程-总办环保工程 | E9: 零星工程 | F9: 战略 | G9: ZY164 | H9: 新建费用类型
A10: 6600070100 | B10: 安全生产-安全生产费 | C10: SAP物料组 | D10: 零星工程-总办安全生产工程 | E10: 零星工程 | F10: 战略 | G10: ZY165 | H10: 新建费用类型
B17: 其他 | C17: SA176 | D17: 主营业务成本-履约成本-保险费（内销） | H17: 预算科目从“其他”调整为“预算【不管控科目】”
C18: SA177 | D18: 主营业务成本-履约成本-报关及港杂费 | H18: 预算科目从“其他”调整为“预算【不管控科目】”
C19: SA191 | D19: 资产处置损益-处置非流动资产利得 | H19: 预算科目从“其他”调整为“预算【不管控科目】”
C20: SA189 | D20: 递延收益-与资产相关的政府补贴 | H20: 预算科目从“其他”调整为“预算【不管控科目】”
C21: SA175 | D21: 主营业务成本-履约成本-保险费（出口） | H21: 预算科目从“其他”调整为“预算【不管控科目】”
C22: SA190 | D22: 其他收益-直接进入其他收益的政府补助 | H22: 预算科目从“其他”调整为“预算【不管控科目】”
C23: SA188 | D23: 长期股权投资-投资成本 | H23: 预算科目从“其他”调整为“预算【不管控科目】”
C28: SA118 | D28: 认证年检登记-抵押登记费 | E28: 销售其他服务费 | H28: 新建预算科目“销售其他服务费”，费用类型SA118归属于新预算科目

Sheet Sheet2
B1: 公司代码 | C1: 公司名称
B2: 1000 | C2: 三安光电股份有限公司 | D2: 陈紫薇
B3: 2010 | C3: 厦门市三安光电科技有限公司 | E3: 无预算
B4: 2020 | C4: 天津三安光电有限公司 | D4: 白国良
B5: 2030 | C5: 安徽三安光电有限公司 | D5: 张晶晶
B6: 2040 | C6: 安徽三安气体有限公司 | D6: 钱桂姐
B7: 2050 | C7: 福建晶安光电有限公司 | D7: 李文博
B8: 2060 | C8: Luminus Inc.
B9: 2070 | C9: Luminus Devices Inc.
B10: 2080 | C10: 朗明纳斯（香港）有限公司
B11: 2090 | C11: 朗明纳斯光电（厦门）有限公司
B12: 2100 | C12: 厦门三安光电有限公司 | D12: 叶巧霜
B13: 2110 | C13: 厦门三安气体有限公司 | E13: 无预算
B14: 2120 | C14: 香港三安光电有限公司
B15: 2130 | C15: 三安光电子信息通讯有限公司
B16: 2140 | C16: 三安先进光通讯有限公司
B17: 2150 | C17: 厦门三安光通讯科技有限公司
B18: 2160 | C18: 厦门市三安半导体科技有限公司 | D18: 邱施睿轶
B19: 2170 | C19: 泉州三安半导体科技有限公司 | D19: 吕艳芳
B20: 2180 | C20: 湖北三安光电有限公司 | D20: 熊洁
B21: 2190 | C21: 北京三安光电有限公司
B22: 2270 | C22: 福建银泽新材料科技有限公司 | D22: 马毅然
B23: 2280 | C23: 湖北艾迈谱光电科技有限公司 | D23: 熊洁
B24: 3010 | C24: 厦门市三安集成电路有限公司 | D24: 纪婷婷
B25: 3020 | C25: 香港三安集成电路科技有限公司
B26: 3040 | C26: 上海三安领翔集成电路有限公司 | D26: 纪婷婷
B27: 3050 | C27: 湖南三安半导体有限责任公司 | D27: 黄黎垚
B28: 3060 | C28: 福建北电新材料科技有限公司 | D28: 黄黎垚 | E28: 无预算
B29: 3070 | C29: 泉州市三安集成电路有限公司 | D29: 许婷婷
B30: 3080 | C30: 泉州市三安光通讯科技有限公司 | D30: 美旋
B31: 3090 | C31: 橙方网络科技有限公司
B32: 3100 | C32: Hunan San'an Halbleiter G
B33: 3110 | C33: 湖南三安半导体科技有限公司 | D33: 黄黎垚
B34: 3120 | C34: 未启用
B35: 3130 | C35: 未启用
B36: 3200 | C36: 重庆三安半导体有限责任公司 | D36: 王旻婧
B37: 5010 | C37: 芜湖安瑞光电有限公司 | D37: 王林
B38: 5020 | C38: 芜湖安瑞光电有限公司西南分公司 | D38: 王林
B39: 5030 | C39: 芜湖安瑞光电有限公司台州分公司 | D39: 王林
B40: 5040 | C40: 安徽三安科技有限公司 | D40: 林雅真
...

Sheet Sheet1
A3: 行标签
A4: IT | C4: 陈曦
A5: 安徽气体
A6: 安瑞
A7: 安瑞市场部
A8: 财务 | C8: 紫薇
A9: 采购 | C9: 家铭，陈宇
A10: 风控 | C10: 赵文倩
A11: 各工厂生产部门
A12: 基建 | C12: 王绿茵
A13: 技术中心
A14: 品管 | C14: 原珍
A15: 人资 | C15: 彭蓉
A16: 生管/采购（关务）
A17: 销售部
A18: 战略 | C18: 劲松，子尧
A19: 证券 | C19: 陈诚仪
A20: 总办 | C20: 妙玲
A21: (空白)
A22: 总计
